<?xml version="1.0" encoding="utf-8"?>
<sdf version="1.11">
  <model name="fpv_drone">
    <link name="base_link">
      <inertial>
        <pose>-0.0024900360513682202 2.23484753574324e-06 -8.7034070390901204e-05 0 0 0</pose>
        <mass>0.65445895682363198</mass>
        <inertia>
          <ixx>0.00039170102862876602</ixx>
          <ixy>-3.0145926617623202e-07</ixy>
          <ixz>2.1749254203583599e-05</ixz>
          <iyy>0.0015943340216900801</iyy>
          <iyz>2.4613123759215701e-08</iyz>
          <izz>0.0017709526193659499</izz>
        </inertia>
      </inertial>
      <collision name="base_link_collision">
        <pose>0 0 0 0 0 0</pose>
        <geometry>
          <mesh>
            <scale>1 1 1</scale>
            <uri>package://fpv_drone/meshes/fpv_drone/base_link.stl</uri>
          </mesh>
        </geometry>
      </collision>
      <visual name="base_link_visual">
        <pose>0 0 0 0 0 0</pose>
        <geometry>
          <mesh>
            <scale>1 1 1</scale>
            <uri>package://fpv_drone/meshes/fpv_drone/base_link.stl</uri>
          </mesh>
        </geometry>
        <material>
          <diffuse>1 1 1 1</diffuse>
          <ambient>1 1 1 1</ambient>
        </material>
      </visual>
    </link>
    
    <link name='imu_link'>

      <inertial>
        <pose>0 0 0 0 0 0</pose>
        <mass>0.15</mass>
        <inertia>
          <ixx>0.00001</ixx>
          <ixy>0</ixy>
          <ixz>0</ixz>
          <iyy>0.00002</iyy>
          <iyz>0</iyz>
          <izz>0.00002</izz>
        </inertia>
      </inertial>

      <sensor name="imu_sensor" type="imu">
        <pose degrees="true">0 0 0 180 0 0</pose>
        <always_on>1</always_on>
        <update_rate>1000.0</update_rate>
      </sensor>

    </link>
    
    <joint name='imu_joint' type='revolute'>
      <child>imu_link</child>
      <parent>base_link</parent>
      <axis>
        <xyz>0 0 1</xyz>
        <limit>
          <lower>0</lower>
          <upper>0</upper>
          <effort>0</effort>
          <velocity>0</velocity>
        </limit>
        <dynamics>
          <damping>1.0</damping>
        </dynamics>
      </axis>
    </joint>
    <joint name="cam_joint" type="fixed">
      <pose relative_to="base_link">0.17054485762608201 -6.3349718311619298e-05 0.0013876838389832999 0 -0.45131006120165101 0</pose>
      <parent>base_link</parent>
      <child>cam_link</child>
      <axis>
        <xyz>0 0 1</xyz>
        <limit>
          <lower>-inf</lower>
          <upper>inf</upper>
        </limit>
        <dynamics>
          <spring_reference>0</spring_reference>
          <spring_stiffness>0</spring_stiffness>
        </dynamics>
      </axis>
    </joint>
    <link name="cam_link">
      <pose relative_to="cam_joint">0 0 0 0 0 0</pose>
      <inertial>
        <pose>-0.0125983648388273 -4.5595211197249598e-07 3.3018888948244098e-05 0 0 0</pose>
        <mass>0.0050361866165823102</mass>
        <inertia>
          <ixx>2.2237273413804201e-07</ixx>
          <ixy>5.4618733559860601e-12</ixy>
          <ixz>2.2495040280196002e-12</ixz>
          <iyy>1.3962063618539699e-07</iyy>
          <iyz>-2.5999079801609699e-10</iyz>
          <izz>1.4066829787496999e-07</izz>
        </inertia>
      </inertial>
      <collision name="cam_link_collision">
        <pose>0 0 0 0 0 0</pose>
        <geometry>
          <mesh>
            <scale>1 1 1</scale>
            <uri>package://fpv_drone/meshes/fpv_drone/cam_link.stl</uri>
          </mesh>
        </geometry>
      </collision>
      <visual name="cam_link_visual">
        <pose>0 0 0 0 0 0</pose>
        <geometry>
          <mesh>
            <scale>1 1 1</scale>
            <uri>package://fpv_drone/meshes/fpv_drone/cam_link.stl</uri>
          </mesh>
        </geometry>
        <material>
          <diffuse>1 1 1 1</diffuse>
          <ambient>1 1 1 1</ambient>
        </material>
      </visual>
    </link>
    <joint name="motor_bl_joint" type="revolute">
      <pose relative_to="base_link">-0.073338665706914205 0.11597758812328 0.017373810535879299 0 0 0</pose>
      <parent>base_link</parent>
      <child>motor_bl_link</child>
      <axis>
        <xyz>0 0 1</xyz>
        <limit>
          <lower>-inf</lower>
          <upper>inf</upper>
        </limit>
        <dynamics>
          <spring_reference>0</spring_reference>
          <spring_stiffness>0</spring_stiffness>
        </dynamics>
      </axis>
    </joint>
    <link name="motor_bl_link">
      <pose relative_to="motor_bl_joint">0 0 0 0 0 0</pose>
      <inertial>
        <pose>0 0 0 0 0 0</pose>
        <mass>0.0057644254150870499</mass>
        <inertia>
          <ixx>1.5110710735372999e-06</ixx>
          <ixy>8.9867273461706195e-10</ixy>
          <ixz>-1.11569795809127e-10</ixz>
          <iyy>1.51182643180542e-06</iyy>
          <iyz>-9.3847817783140901e-11</iyz>
          <izz>2.8134456374538499e-06</izz>
        </inertia>
      </inertial>
      <collision name="motor_bl_link_collision">
        <pose>0 0 0 0 0 0</pose>
        <geometry>
          <mesh>
            <scale>1 1 1</scale>
            <uri>package://fpv_drone/meshes/fpv_drone/motor_bl_link.stl</uri>
          </mesh>
        </geometry>
      </collision>
      <visual name="motor_bl_link_visual">
        <pose>0 0 0 0 0 0</pose>
        <geometry>
          <mesh>
            <scale>1 1 1</scale>
            <uri>package://fpv_drone/meshes/fpv_drone/motor_bl_link.stl</uri>
          </mesh>
        </geometry>
        <material>
          <diffuse>0 0.0196078438 0.0735294148 1</diffuse>
          <ambient>0 0.0196078438 0.0735294148 1</ambient>
        </material>
      </visual>
    </link>
    <joint name="motor_br_joint" type="revolute">
      <pose relative_to="base_link">-0.073257074139625206 -0.116168033240677 0.017373810535879199 0 0 0</pose>
      <parent>base_link</parent>
      <child>motor_br_link</child>
      <axis>
        <xyz>0 0 1</xyz>
        <limit>
          <lower>-inf</lower>
          <upper>inf</upper>
        </limit>
        <dynamics>
          <spring_reference>0</spring_reference>
          <spring_stiffness>0</spring_stiffness>
        </dynamics>
      </axis>
    </joint>
    <link name="motor_br_link">
      <pose relative_to="motor_br_joint">0 0 0 0 0 0</pose>
      <inertial>
        <pose>0 0 0 0 0 0</pose>
        <mass>0.0057655799391228999</mass>
        <inertia>
          <ixx>1.5115000126970599e-06</ixx>
          <ixy>-5.1134706345073895e-10</ixy>
          <ixz>-1.72030740671937e-10</ixz>
          <iyy>1.5128610789386601e-06</iyy>
          <iyz>1.40329523816954e-11</iyz>
          <izz>2.81490187063425e-06</izz>
        </inertia>
      </inertial>
      <collision name="motor_br_link_collision">
        <pose>0 0 0 0 0 0</pose>
        <geometry>
          <mesh>
            <scale>1 1 1</scale>
            <uri>package://fpv_drone/meshes/fpv_drone/motor_br_link.stl</uri>
          </mesh>
        </geometry>
      </collision>
      <visual name="motor_br_link_visual">
        <pose>0 0 0 0 0 0</pose>
        <geometry>
          <mesh>
            <scale>1 1 1</scale>
            <uri>package://fpv_drone/meshes/fpv_drone/motor_br_link.stl</uri>
          </mesh>
        </geometry>
        <material>
          <diffuse>1 1 1 1</diffuse>
          <ambient>1 1 1 1</ambient>
        </material>
      </visual>
    </link>
    <joint name="motor_fl_joint" type="revolute">
      <pose relative_to="base_link">0.14301689517854599 0.11605251983675199 0.017373810535879299 0 0 0</pose>
      <parent>base_link</parent>
      <child>motor_fl_link</child>
      <axis>
        <xyz>0 0 1</xyz>
        <limit>
          <lower>-inf</lower>
          <upper>inf</upper>
        </limit>
        <dynamics>
          <spring_reference>0</spring_reference>
          <spring_stiffness>0</spring_stiffness>
        </dynamics>
      </axis>
    </joint>
    <link name="motor_fl_link">
      <pose relative_to="motor_fl_joint">0 0 0 0 0 0</pose>
      <inertial>
        <pose>-1.8509378795439299e-05 -2.9140809716665698e-07 -0.0152172066615232 0 0 0</pose>
        <mass>0.00576557526611092</mass>
        <inertia>
          <ixx>1.5114998641275299e-06</ixx>
          <ixy>-5.13356130432017e-10</ixy>
          <ixz>-1.71497065666247e-10</ixz>
          <iyy>1.5128588973097699e-06</iyy>
          <iyz>1.4403605568426899e-11</iyz>
          <izz>2.8148994630456798e-06</izz>
        </inertia>
      </inertial>
      <collision name="motor_fl_link_collision">
        <pose>0 0 0 0 0 0</pose>
        <geometry>
          <mesh>
            <scale>1 1 1</scale>
            <uri>package://fpv_drone/meshes/fpv_drone/motor_fl_link.stl</uri>
          </mesh>
        </geometry>
      </collision>
      <visual name="motor_fl_link_visual">
        <pose>0 0 0 0 0 0</pose>
        <geometry>
          <mesh>
            <scale>1 1 1</scale>
            <uri>package://fpv_drone/meshes/fpv_drone/motor_fl_link.stl</uri>
          </mesh>
        </geometry>
        <material>
          <diffuse>0 0.0196078438 0.0735294148 1</diffuse>
          <ambient>0 0.0196078438 0.0735294148 1</ambient>
        </material>
      </visual>
    </link>
    <joint name="motor_fr_joint" type="revolute">
      <pose relative_to="base_link">0.14312691294383101 -0.116093156523998 0.017373810535891002 0 0 0</pose>
      <parent>base_link</parent>
      <child>motor_fr_link</child>
      <axis>
        <xyz>0 0 1</xyz>
        <limit>
          <lower>-inf</lower>
          <upper>inf</upper>
        </limit>
        <dynamics>
          <spring_reference>0</spring_reference>
          <spring_stiffness>0</spring_stiffness>
        </dynamics>
      </axis>
    </joint>
    <link name="motor_fr_link">
      <pose relative_to="motor_fr_joint">0 0 0 0 0 0</pose>
      <inertial>
        <pose>-2.3850090994814701e-05 1.5411770194484501e-06 -0.015218397996398 0 0 0</pose>
        <mass>0.0057644238721742801</mass>
        <inertia>
          <ixx>1.51106803466048e-06</ixx>
          <ixy>8.9878373088590903e-10</ixy>
          <ixz>-1.1158323696386001e-10</ixz>
          <iyy>1.51182695549402e-06</iyy>
          <iyz>-9.3390680679281306e-11</iyz>
          <izz>2.8134431668343801e-06</izz>
        </inertia>
      </inertial>
      <collision name="motor_fr_link_collision">
        <pose>0 0 0 0 0 0</pose>
        <geometry>
          <mesh>
            <scale>1 1 1</scale>
            <uri>package://fpv_drone/meshes/fpv_drone/motor_fr_link.stl</uri>
          </mesh>
        </geometry>
      </collision>
      <visual name="motor_fr_link_visual">
        <pose>0 0 0 0 0 0</pose>
        <geometry>
          <mesh>
            <scale>1 1 1</scale>
            <uri>package://fpv_drone/meshes/fpv_drone/motor_fr_link.stl</uri>
          </mesh>
        </geometry>
        <material>
          <diffuse>0.990196109 1 1 1</diffuse>
          <ambient>0.990196109 1 1 1</ambient>
        </material>
      </visual>
    </link>
  </model>
</sdf>
