<?xml version="1.0" encoding="utf-8"?>
<sdf version="1.11">
  <model name="fpv_drone">
    <link name="base_link">
      <inertial>
        <pose>-0.0098031702924297193 0.00071784904626204899 0.00067782125058207104 0 0 0</pose>
        <mass>0.67102433923775995</mass>
        <inertia>
          <ixx>0.00039924393155537198</ixx>
          <ixy>1.02532609423855e-07</ixy>
          <ixz>1.64679626990287e-05</ixz>
          <iyy>0.00164838910850328</iyy>
          <iyz>-2.3372063608166999e-08</iyz>
          <izz>0.0018643915745464601</izz>
        </inertia>
      </inertial>
      <collision name="base_link_collision">
        <pose>0 0 0 0 0 0</pose>
        <geometry>
          <mesh>
            <scale>1 1 1</scale>
            <uri>package://fpv_drone/meshes/fpv_drone/base_link.stl</uri>
          </mesh>
        </geometry>
      </collision>
      <visual name="base_link_visual">
        <pose>0 0 0 0 0 0</pose>
        <geometry>
          <mesh>
            <scale>1 1 1</scale>
            <uri>package://fpv_drone/meshes/fpv_drone/base_link.stl</uri>
          </mesh>
        </geometry>
        <material>
          <diffuse>1 1 1 1</diffuse>
          <ambient>1 1 1 1</ambient>
        </material>
      </visual>
    </link>
    <joint name="cam_joint" type="fixed">
      <pose relative_to="base_link">0.16345999999999999 -0.00021929999999999999 0.0023035999999999998 0 -0.47787000000000002 0</pose>
      <parent>base_link</parent>
      <child>cam_link</child>
      <axis>
        <xyz>0 0 1</xyz>
        <limit>
          <lower>-inf</lower>
          <upper>inf</upper>
        </limit>
        <dynamics>
          <spring_reference>0</spring_reference>
          <spring_stiffness>0</spring_stiffness>
        </dynamics>
      </axis>
    </joint>
    <link name="cam_link">
      <pose relative_to="cam_joint">0 0 0 0 0 0</pose>
      <inertial>
        <pose>-0.012598364936259101 -4.5618181184967098e-07 3.3019328935068897e-05 0 0 0</pose>
        <mass>0.00503618642395217</mass>
        <inertia>
          <ixx>2.22372718345281e-07</ixx>
          <ixy>5.4652069326813298e-12</ixy>
          <ixz>2.2452920742459401e-12</ixz>
          <iyy>1.39620632564017e-07</iyy>
          <iyz>-2.5998533194052801e-10</iyz>
          <izz>1.4066828276679599e-07</izz>
        </inertia>
      </inertial>
      <collision name="cam_link_collision">
        <pose>0 0 0 0 0 0</pose>
        <geometry>
          <mesh>
            <scale>1 1 1</scale>
            <uri>package://fpv_drone/meshes/fpv_drone/cam_link.stl</uri>
          </mesh>
        </geometry>
      </collision>
      <visual name="cam_link_visual">
        <pose>0 0 0 0 0 0</pose>
        <geometry>
          <mesh>
            <scale>1 1 1</scale>
            <uri>package://fpv_drone/meshes/fpv_drone/cam_link.stl</uri>
          </mesh>
        </geometry>
        <material>
          <diffuse>1 1 1 1</diffuse>
          <ambient>1 1 1 1</ambient>
        </material>
      </visual>
    </link>
    <joint name="motor_bl_joint" type="revolute">
      <pose relative_to="base_link">-0.081059999999999993 0.11675000000000001 0.018367000000000001 0 0 0</pose>
      <parent>base_link</parent>
      <child>motor_bl_link</child>
      <axis>
        <xyz>0 0 -1</xyz>
        <limit>
          <lower>-inf</lower>
          <upper>inf</upper>
        </limit>
        <dynamics>
          <spring_reference>0</spring_reference>
          <spring_stiffness>0</spring_stiffness>
        </dynamics>
      </axis>
    </joint>
    <link name="motor_bl_link">
      <pose relative_to="motor_bl_joint">0 0 0 0 0 0</pose>
      <inertial>
        <pose>-7.0888682945913196e-07 8.3007815626506797e-06 -0.0098648166373760705 0 0 0</pose>
        <mass>0.0027112613984709298</mass>
        <inertia>
          <ixx>1.2785774886632501e-06</ixx>
          <ixy>-3.36932094759357e-10</ixy>
          <ixz>5.1918005529927397e-11</ixz>
          <iyy>1.27744986592196e-06</iyy>
          <iyz>2.0425406999255101e-10</iyz>
          <izz>2.5415139926155402e-06</izz>
        </inertia>
      </inertial>
      <collision name="motor_bl_link_collision">
        <pose>0 0 0 0 0 0</pose>
        <geometry>
          <mesh>
            <scale>1 1 1</scale>
            <uri>package://fpv_drone/meshes/fpv_drone/motor_bl_link.stl</uri>
          </mesh>
        </geometry>
      </collision>
      <visual name="motor_bl_link_visual">
        <pose>0 0 0 0 0 0</pose>
        <geometry>
          <mesh>
            <scale>1 1 1</scale>
            <uri>package://fpv_drone/meshes/fpv_drone/motor_bl_link.stl</uri>
          </mesh>
        </geometry>
        <material>
          <diffuse>0.990196109 1 1 1</diffuse>
          <ambient>0.990196109 1 1 1</ambient>
        </material>
      </visual>
    </link>
    <joint name="motor_br_joint" type="revolute">
      <pose relative_to="base_link">-0.080978999999999995 -0.11539000000000001 0.018367000000000001 0 0 0</pose>
      <parent>base_link</parent>
      <child>motor_br_link</child>
      <axis>
        <xyz>0 0 1</xyz>
        <limit>
          <lower>-inf</lower>
          <upper>inf</upper>
        </limit>
        <dynamics>
          <spring_reference>0</spring_reference>
          <spring_stiffness>0</spring_stiffness>
        </dynamics>
      </axis>
    </joint>
    <link name="motor_br_link">
      <pose relative_to="motor_br_joint">0 0 0 0 0 0</pose>
      <inertial>
        <pose>-1.81484937635812e-05 -6.6428912028904099e-06 -0.0098658530815737295 0 0 0</pose>
        <mass>0.0027100240363586801</mass>
        <inertia>
          <ixx>1.2795229833430001e-06</ixx>
          <ixy>2.28029270143057e-10</ixy>
          <ixz>1.4943179790997099e-10</ixz>
          <iyy>1.2753945163344801e-06</iyy>
          <iyz>-2.14348420735935e-10</iyz>
          <izz>2.5404116820245501e-06</izz>
        </inertia>
      </inertial>
      <collision name="motor_br_link_collision">
        <pose>0 0 0 0 0 0</pose>
        <geometry>
          <mesh>
            <scale>1 1 1</scale>
            <uri>package://fpv_drone/meshes/fpv_drone/motor_br_link.stl</uri>
          </mesh>
        </geometry>
      </collision>
      <visual name="motor_br_link_visual">
        <pose>0 0 0 0 0 0</pose>
        <geometry>
          <mesh>
            <scale>1 1 1</scale>
            <uri>package://fpv_drone/meshes/fpv_drone/motor_br_link.stl</uri>
          </mesh>
        </geometry>
        <material>
          <diffuse>0 0.0196078438 0.0735294148 1</diffuse>
          <ambient>0 0.0196078438 0.0735294148 1</ambient>
        </material>
      </visual>
    </link>
    <joint name="motor_fl_joint" type="revolute">
      <pose relative_to="base_link">0.1353 0.11683 0.018367000000000001 0 0 0</pose>
      <parent>base_link</parent>
      <child>motor_fl_link</child>
      <axis>
        <xyz>0 0 1</xyz>
        <limit>
          <lower>-inf</lower>
          <upper>inf</upper>
        </limit>
        <dynamics>
          <spring_reference>0</spring_reference>
          <spring_stiffness>0</spring_stiffness>
        </dynamics>
      </axis>
    </joint>
    <link name="motor_fl_link">
      <pose relative_to="motor_fl_joint">0 0 0 0 0 0</pose>
      <inertial>
        <pose>-1.81424024814358e-05 -6.6426895608540101e-06 -0.0098658538808714807 0 0 0</pose>
        <mass>0.0027100221692816298</mass>
        <inertia>
          <ixx>1.27952227945784e-06</ixx>
          <ixy>2.2847849647977099e-10</ixy>
          <ixz>1.4930601141423799e-10</ixz>
          <iyy>1.2753947906661599e-06</iyy>
          <iyz>-2.1443454686733801e-10</iyz>
          <izz>2.5404112857282099e-06</izz>
        </inertia>
      </inertial>
      <collision name="motor_fl_link_collision">
        <pose>0 0 0 0 0 0</pose>
        <geometry>
          <mesh>
            <scale>1 1 1</scale>
            <uri>package://fpv_drone/meshes/fpv_drone/motor_fl_link.stl</uri>
          </mesh>
        </geometry>
      </collision>
      <visual name="motor_fl_link_visual">
        <pose>0 0 0 0 0 0</pose>
        <geometry>
          <mesh>
            <scale>1 1 1</scale>
            <uri>package://fpv_drone/meshes/fpv_drone/motor_fl_link.stl</uri>
          </mesh>
        </geometry>
        <material>
          <diffuse>0 0.0196078438 0.0735294148 1</diffuse>
          <ambient>0 0.0196078438 0.0735294148 1</ambient>
        </material>
      </visual>
    </link>
    <joint name="motor_fr_joint" type="revolute">
      <pose relative_to="base_link">0.13541 -0.11532000000000001 0.018367000000000001 0 0 0</pose>
      <parent>base_link</parent>
      <child>motor_fr_link</child>
      <axis>
        <xyz>0 0 -1</xyz>
        <limit>
          <lower>-inf</lower>
          <upper>inf</upper>
        </limit>
        <dynamics>
          <spring_reference>0</spring_reference>
          <spring_stiffness>0</spring_stiffness>
        </dynamics>
      </axis>
    </joint>
    <link name="motor_fr_link">
      <pose relative_to="motor_fr_joint">0 0 0 0 0 0</pose>
      <inertial>
        <pose>-7.2431229702907295e-07 8.2792567882850105e-06 -0.0098648170791148498 0 0 0</pose>
        <mass>0.0027112633854980499</mass>
        <inertia>
          <ixx>1.2785793472497299e-06</ixx>
          <ixy>-3.3825607133766902e-10</ixy>
          <ixz>5.18805140288672e-11</ixz>
          <iyy>1.27745085479085e-06</iyy>
          <iyz>2.04256448431118e-10</iyz>
          <izz>2.5415168031641599e-06</izz>
        </inertia>
      </inertial>
      <collision name="motor_fr_link_collision">
        <pose>0 0 0 0 0 0</pose>
        <geometry>
          <mesh>
            <scale>1 1 1</scale>
            <uri>package://fpv_drone/meshes/fpv_drone/motor_fr_link.stl</uri>
          </mesh>
        </geometry>
      </collision>
      <visual name="motor_fr_link_visual">
        <pose>0 0 0 0 0 0</pose>
        <geometry>
          <mesh>
            <scale>1 1 1</scale>
            <uri>package://fpv_drone/meshes/fpv_drone/motor_fr_link.stl</uri>
          </mesh>
        </geometry>
        <material>
          <diffuse>0.990196109 1 1 1</diffuse>
          <ambient>0.990196109 1 1 1</ambient>
        </material>
      </visual>
    </link>
  </model>
</sdf>
